Workbook

Sheet Cover
B2: 운빨존많겜 테스트 케이스 개요
G4: 게임명: | H4: 운빨존많겜 | K4: 목차
G5: 개발/유통: | H5: 111퍼센트
G6: 플랫폼: | H6: 모바일 | K6: -표지(개요, 선택 사유)
G7: 엔진: | H7: 유니티 | K7: -프로젝트 진행율
G8: 장르: | H8: 전략 디펜스 | K8: -TC_초기구동 (필수 포함 항목)
G9: 주요 타겟: | H9: 10~30 캐주얼 게이머 | K9: -TC_인게임 (지정 항목)
G10: 테스트 빌드: | H10: 1.8.9 (Live)
G11: 테스트 플랫폼: | H11: Android
B13: 레퍼런스 선택 사유
B14: 운빨존많겜은 실제로 플레이 경험이 있어, 직접 해본 경험을 바탕으로 다양한 테스트 상황을 떠올리기 좋았습니다. 다양한 유닛 소환과 배치, 강화, 매칭, 협동 전투 등, 전반적으로 여러 기능이 복합적으로 작동하는 구조이기 때문에 QA의 시선에서 다양한 시나리오를 직접 경험하고 테스트 케이스로 설계해보기에 적합하다고 생각해 선택했습니다.

Sheet 프로젝트 진행율
B2: QA Test Dashboard | AC2: 구분 | AD2: Pass | AE2: Fail | AF2: Blocked | AG2: Not Tested | AH2: 전체 | AI2: Pass율 | AJ2: Fail율
AC3: 초기구동 | AD3: =COUNTIFS(TC_초기구동!I:I,"Pass") -> 34 | AE3: =COUNTIFS(TC_초기구동!I:I, "Fail") -> 0 | AF3: =COUNTIFS(TC_초기구동!I:I, "Blocked") -> 0 | AG3: =COUNTIFS(TC_초기구동!I:I, "Not Tested") -> 0 | AH3: =COUNTA(TC_초기구동!I:I)-1 -> 34 | AI3: =IF(AH3=0, 0, AD3/AH3) -> 1 | AJ3: =AE3/AH3 -> 0
B4: % of Test Cases Pass | I4: % of Test Cases Fail | AC4: 인게임 | AD4: =COUNTIFS(TC_인게임!I:I,"Pass") -> 81 | AE4: =COUNTIFS(TC_인게임!I:I, "Fail") -> 0 | AF4: =COUNTIFS(TC_인게임!I:I, "Blocked") -> 1 | AG4: =COUNTIFS(TC_인게임!I:I, "Not Tested") -> 0 | AH4: =COUNTA(TC_인게임!I:I)-1 -> 82 | AI4: =IF(AH4=0, 0, AD4/AH4) -> 0.98780488 | AJ4: =AE4/AH4 -> 0
B5: =AVERAGE(AI3:AI4) -> 0.99390244 | I5: =AVERAGE(AJ3:AJ4) -> 0
B8: TC_초기구동
D9: Count | F9: Progress
B10: 전체 진행율 | D10: =COUNTA(TC_초기구동!I:I)-1 -> 34 | F10: =SUM(AD3,AE3,AF3,AG3)/D10 -> 1
B11: Pass Rate | D11: =COUNTIF(TC_초기구동!I:I,"pass") -> 34 | F11: =AD3/D10 -> 1
B13: TC_인게임
D14: Count | F14: Progress
B15: 전체 진행율 | D15: =COUNTA(TC_인게임!I:I)-1 -> 82 | F15: =SUM(AD4,AE4,AF4,AG4)/D15 -> 1
B16: Pass Rate | D16: =COUNTIF(TC_인게임!I:I,"pass") -> 81 | F16: =AD4/D15 -> 0.98780488

Sheet TC_초기구동
A1: No. | B1: 우선순위 | C1: 대분류 | D1: 중분류 | E1: 소분류 | F1: 사전 조건 | G1: 테스트 내용 | H1: 기대 결과 | I1: 실제 결과 | J1: 테스트 수행자 | K1: 수행 날짜 | L1: 비고
A2: 1 | B2: High | C2: 앱 설치 | D2: 정상 설치 | E2: 스토어 설치 | F2: 스토어 접근 가능 | G2: 스토어에서 게임 설치 진행 | H2: 설치가 정상 완료되고 앱 아이콘이 생성됨 | I2: Pass | J2: 김가이 | K2: 2026.02.02 | N2: Pass
A3: 2 | B3: Medium | D3: 예외 처리 | E3: 저장 공간 부족 | F3: 기기 저장 공간 부족 상태 | G3: 기기 저장 공간 부족 상태에서 설치 시도 | H3: 설치 불가 안내 메시지 노출 | I3: Pass | J3: 김가이 | K3: 2026.02.02 | N3: Fail
A4: 3 | B4: Medium | D4: 재설치 | E4: 데이터 초기화 | F4: 기존 앱 데이터 삭제 | G4: 앱 삭제 후 재설치 진행 | H4: 정상 설치되며 실행 시 오류가 발생하지 않음 | I4: Pass | J4: 김가이 | K4: 2026.02.02 | N4: Blocked
A5: 4 | B5: High | C5: 앱 실행 | D5: 최초 실행 | E5: 로딩화면 | F5: 앱 설치 완료 | G5: 앱 최초 실행 | H5: 로딩 화면이 정상 노출됨 | I5: Pass | J5: 김가이 | K5: 2026.02.02 | N5: Not Tested
A6: 5 | B6: High | D6: 상태 전환 | E6: 백그라운드 | F6: 로딩 중 | G6: 로딩 중 홈 버튼으로 백그라운드 전환 후 복귀 | H6: 비정상 종료 없이 이어서 진행됨 | I6: Pass | J6: 김가이 | K6: 2026.02.02 | N6: N/A
A7: 6 | B7: Medium | D7: 재실행 | E7: 강제 종료 | F7: 앱 실행 중 | G7: 앱 강제 종료 후 재실행 | H7: 정상적으로 앱이 실행됨 | I7: Pass | J7: 김가이 | K7: 2026.02.02
A8: 7 | B8: High | C8: 권한 | D8: 필수 권한 | E8: 알림 | F8: 최초 실행 | G8: 알림 권한 요청 팝업 확인 | H8: 알림 권한 요청 팝업이 노출됨 | I8: Pass | J8: 김가이 | K8: 2026.02.02
A9: 8 | B9: High | D9: 필수 권한 | E9: 알림 거부 | F9: 알림 권한 요청 상태 | G9: 알림 권한 허용 안함 선택 | H9: 게임이 정상적으로 진행됨 | I9: Pass | J9: 김가이 | K9: 2026.02.02
A10: 9 | B10: Medium | C10: 약관 | D10: 접근 경로 | E10: 설정 메뉴 | F10: 튜토리얼 완료 | G10: 설정 메뉴 진입 | H10: 설정 화면이 정상 노출됨 | I10: Pass | J10: 김가이 | K10: 2026.02.02
A11: 10 | B11: Medium | D11: 외부 페이지 | E11: 이용 약관 | F11: 설정 메뉴 진입 | G11: 이용 약관 선택 | H11: 외부 인터넷 페이지로 이동함 | I11: Pass | J11: 김가이 | K11: 2026.02.02
A12: 11 | B12: Medium | D12: 외부 페이지 | E12: 이용 약관 페이지 로딩 | F12: 네트워크 정상 | G12: 이용 약관 페이지가 정상적으로 로드되는지 확인 | H12: 이용 약관 페이지가 정상 표시됨 | I12: Pass | J12: 김가이 | K12: 2026.02.02
A13: 12 | B13: Medium | D13: 외부 페이지 | E13: 이용 약관 페이지 오류 | F13: 네트워크 차단 | G13: 이용 약관 선택 | H13: 오류 또는 로딩 실패 상태가 명확히 표시됨 | I13: Pass | J13: 김가이 | K13: 2026.02.02
A14: 13 | B14: Medium | D14: 외부 페이지 | E14: 이용 약관 복귀 | F14: 이용 약관 페이지 진입 | G14: 뒤로가기 버튼 선택 | H14: 게임으로 정상 복귀됨 | I14: Pass | J14: 김가이 | K14: 2026.02.02
A15: 14 | B15: Medium | D15: 외부 페이지 | E15: 개인정보 처리방침 | F15: 설정 메뉴 진입 | G15: 개인정보 처리방침 선택 | H15: 외부 인터넷 페이지로 이동함 | I15: Pass | J15: 김가이 | K15: 2026.02.02
A16: 15 | B16: Medium | D16: 외부 페이지 | E16: 개인정보 처리방침 페이지 로딩 | F16: 네트워크 정상 | G16: 개인정보 처리방침 페이지가 정상적으로 로드되는지 확인 | H16: 개인정보 처리방침 페이지가 정상 표시됨 | I16: Pass | J16: 김가이 | K16: 2026.02.02
A17: 16 | B17: Medium | D17: 외부 페이지 | E17: 개인정보 처리방침 페이지 오류 | F17: 네트워크 차단 | G17: 개인정보 처리방침 선택 | H17: 오류 또는 로딩 실패 상태가 명확히 표시됨 | I17: Pass | J17: 김가이 | K17: 2026.02.02
A18: 17 | B18: Medium | D18: 외부 페이지 | E18: 개인정보 처리방침 복귀 | F18: 개인정보 처리방침 페이지 진입 | G18: 뒤로가기 버튼 선택 | H18: 게임으로 정상 복귀됨 | I18: Pass | J18: 김가이 | K18: 2026.02.02
A19: 18 | B19: Low | D19: 외부 페이지 | E19: URL 유효성 | F19: 네트워크 정상 | G19: 각 페이지 URL 확인 | H19: 잘못된 페이지(404, 빈 페이지 등)가 노출되지 않음 | I19: Pass | J19: 김가이 | K19: 2026.02.02
A20: 19 | B20: High | C20: 로그인 | D20: 접근 경로 | E20: 계정 연동 버튼 | F20: 튜토리얼 완료 | G20: 설정 메뉴 진입 후 계정 연동 버튼 선택 | H20: 로그인 방식 선택 화면이 노출됨 | I20: Pass | J20: 김가이 | K20: 2026.02.02
A21: 20 | B21: High | D21: 로그인 방식 | E21: Google 로그인 | F21: 로그인 방식 선택 화면 | G21: Google로 로그인 선택 | H21: 이용 약관 및 개인정보 처리방침 동의 UI가 노출됨 | I21: Pass | J21: 김가이 | K21: 2026.02.02
A22: 21 | B22: High | D22: 로그인 방식 | E22: Apple 로그인 | F22: 로그인 방식 선택 화면 | G22: Apple로 로그인 선택 | H22: 이용 약관 및 개인정보 처리방침 동의 UI가 노출됨 | I22: Pass | J22: 김가이 | K22: 2026.02.02
A23: 22 | B23: High | D23: 약관 동의 | E23: 약관 동의 UI 노출 | F23: 로그인 방식 선택 후 | G23: 약관 동의 UI 구성 확인 | H23: 동의 버튼이 정상 노출됨 | I23: Pass | J23: 김가이 | K23: 2026.02.02
A24: 23 | B24: Medium | D24: 약관 링크 | E24: 이용 약관 | F24: 약관 동의 UI 노출 | G24: 이용 약관 링크 선택 | H24: 외부 인터넷 페이지로 이동함 | I24: Pass | J24: 김가이 | K24: 2026.02.02
A25: 24 | B25: Medium | D25: 약관 링크 | E25: 개인정보 처리방침 | F25: 약관 동의 UI 노출 | G25: 개인정보 처리방침 링크 선택 | H25: 외부 인터넷 페이지로 이동함 | I25: Pass | J25: 김가이 | K25: 2026.02.02
A26: 25 | B26: High | D26: 약관 동의 | E26: 약관 동의 진행 | F26: 약관 동의 UI 노출 | G26: 동의 버튼 선택 | H26: 플랫폼 계정 선택 화면으로 이동함 | I26: Pass | J26: 김가이 | K26: 2026.02.02
A27: 26 | B27: High | D27: 계정 선택 | E27: Google 계정 | F27: Google 로그인 선택 및 약관 동의 | G27: Google 계정 선택 | H27: 계정 연동이 정상 완료됨 | I27: Pass | J27: 김가이 | K27: 2026.02.02
A28: 27 | B28: High | D28: 계정 선택 | E28: Apple 계정 | F28: Apple 로그인 선택 및 약관 동의 | G28: Apple 계정 선택 | H28: 계정 연동이 정상 완료됨 | I28: Pass | J28: 김가이 | K28: 2026.02.02
A29: 28 | B29: High | D29: 계정 충돌 | E29: 충돌 안내 노출 | F29: 이미 연동된 계정 선택 | G29: 계정 연동 진행 | H29: 기존 계정 / 진행 중 계정 선택 UI가 노출됨 | I29: Pass | J29: 김가이 | K29: 2026.02.02
A30: 29 | B30: High | D30: 계정 충돌 | E30: 기존 계정 선택 | F30: 충돌 안내 노출 | G30: 기존 계정 선택 | H30: 기존 계정 데이터로 정상 연동됨 | I30: Pass | J30: 김가이 | K30: 2026.02.02
A31: 30 | B31: High | D31: 계정 충돌 | E31: 진행 중 계정 선택 | F31: 충돌 안내 노출 | G31: 진행 중 계정 선택 | H31: 현재 진행 데이터가 유지된 채 연동됨 | I31: Pass | J31: 김가이 | K31: 2026.02.02
A32: 31 | B32: High | D32: 계정 충돌 | E32: 취소 | F32: 충돌 안내 노출 | G32: 뒤로가기 버튼 선택 | H32: 계정 연동 이전 화면으로 복귀됨 | I32: Pass | J32: 김가이 | K32: 2026.02.02
... A35: 34 | B35: Medium | D35: 결과 | E35: 연동 상태 | F35: 연동 완료 | G35: 설정 화면 확인 | H35: 계정 연동 완료 상태가 표시됨 | I35: Pass | J35: 김가이 | K35: 2026.02.02

Sheet TC_인게임
A1: No. | B1: 우선순위 | C1: 대분류 | D1: 중분류 | E1: 소분류 | F1: 사전 조건 | G1: 테스트 내용 | H1: 기대 결과 | I1: 실제 결과 | J1: 테스트 수행자 | K1: 수행 날짜 | L1: 비고
A2: 1 | B2: High | C2: 매칭 | D2: 매칭 시작 | E2: 빠른 시작 버튼 | F2: 로비 진입 상태 | G2: 빠른 시작 버튼 클릭 시 매칭 큐 진입 | H2: 매칭 대기 상태 진입 | I2: Pass | J2: 김가이 | K2: 2026.02.02 | N2: Pass
A3: 2 | B3: High | D3: 매칭 대기 | E3: 대기 시간 표기 | F3: 매칭 대기 중 | G3: 유저 수에 따라 대기 상태 시간 실시간 표시 확인 | H3: 대기 시간 실시간 갱신 확인 | I3: Pass | J3: 김가이 | K3: 2026.02.02 | N3: Fail
A4: 3 | B4: High | D4: 매칭 결과 | E4: 매칭 성공 | F4: 매칭 요청 후 성공 | G4: 매칭 성공 시 로딩 화면 이동 확인 | H4: 매칭 성공 후 로딩 화면으로 이동 | I4: Pass | J4: 김가이 | K4: 2026.02.02 | N4: Blocked
A5: 4 | B5: Medium | D5: 매칭 결과 | E5: 매칭 실패 | F5: 매칭 대기 중 일정 시간 내 매칭 실패 | G5: 매칭 실패 팝업 출력 여부 확인 | H5: 매칭 실패 후 로비 복귀 | I5: Blocked | K5: 2026.02.02 | N5: Not Tested
A6: 5 | B6: Medium | D6: 매칭 취소 | E6: 사용자 수동 취소 | F6: 매칭 대기 중 취소 | G6: 취소 버튼 클릭 시 매칭 대기 상태 종료 확인 | H6: 매칭 취소 후 로비 복귀 | I6: Pass | J6: 김가이 | K6: 2026.02.02 | N6: N/A
A7: 6 | B7: High | D7: 매칭 진입 | E7: 게임 시작 연출 | F7: 매칭 성공 후 로딩 완료 | G7: 2명의 플레이어 프로필 노출되며 시작 연출 확인 | H7: 아이콘, 레벨, 닉네임이 정확하게 표시되며 오프닝 연출이 정상 표시됨 | I7: Pass | J7: 김가이 | K7: 2026.02.02
A8: 7 | B8: Medium | C8: 인게임 UI | D8: 유저 정보 | E8: 사용자 프로필 이미지 표시 | F8: 게임 진행 중 | G8: 좌측 상단 유저 프로필 이미지 표시 확인 | H8: 사용자가 설정한 프로필 이미지 정상 표시 | I8: Pass | J8: 김가이 | K8: 2026.02.03
A9: 8 | B9: Medium | E9: 사용자 레벨 표시 | F9: 게임 진행 중 | G9: 좌측 상단 유저 레벨 표시 확인 | H9: 사용자의 계정 레벨 정상 표시 | I9: Pass | J9: 김가이 | K9: 2026.02.03
A10: 9 | B10: Medium | E10: 사용자 닉네임 표시 | F10: 게임 진행 중 | G10: 좌측 상단 유저 닉네임 표시 확인 | H10: 사용자의 닉네임 정상 표시 | I10: Pass | J10: 김가이 | K10: 2026.02.03
A11: 10 | B11: Medium | E11: 동료 프로필 이미지 표시 | F11: 게임 진행 중 | G11: 우측 상단 유저 프로필 이미지 표시 확인 | H11: 동료가 설정한 프로필 이미지 정상 표시 | I11: Pass | J11: 김가이 | K11: 2026.02.03
A12: 11 | B12: Medium | E12: 동료 레벨 표시 | F12: 게임 진행 중 | G12: 우측 상단 유저 레벨 표시 확인 | H12: 동료의 계정 레벨 정상 표시 | I12: Pass | J12: 김가이 | K12: 2026.02.03
A13: 12 | B13: Medium | E13: 동료 닉네임 표시 | F13: 게임 진행 중 | G13: 우측 상단 유저 닉네임 표시 확인 | H13: 동료의 닉네임 정상 표시 | I13: Pass | J13: 김가이 | K13: 2026.02.03
A14: 13 | B14: Medium | D14: 진행 상태 표시 | E14: 웨이브 및 타이머 | F14: 게임 진행 중 | G14: 웨이브 및 타이머가 상단 중앙에 표시되는지 확인 | H14: 현재 웨이브 및 남은 시간 정상 표시 | I14: Pass | J14: 김가이 | K14: 2026.02.03
A15: 14 | B15: High | E15: 몬스터 수 UI | F15: 게임 진행 중 | G15: 현재 몬스터 수 / 최대치가 상단 중앙에 정상 표시 되는지 확인 | H15: 현재 몬스터 수 / 최대 몬스터 수 형태로 수치가 실시간으로 갱신 표시됨 | I15: Pass | J15: 김가이 | K15: 2026.02.03
A16: 15 | B16: High | E16: 임계 수치 시각 효과 | F16: 현재 필드 위 몬스터 수 70 이상 도달 | G16: 수치가 임계치에 가까울 때 강조되는지 확인 | H16: 주의 유도 UI가 표시됨 | I16: Pass | J16: 김가이 | K16: 2026.02.03
A17: 16 | B17: High | D17: 알림 표시 | E17: 소환 결과 알림 | F17: 고등급 영웅 소환 성공 | G17: 고등급 영웅 소환 시 알림 표시 여부 확인 | H17: "[닉네임]님이 [영웅명][등급] 영웅을 소환!" 문구 출력 | I17: Pass | J17: 김가이 | K17: 2026.02.03
A18: 17 | B18: Medium | E18: 소환 결과 알림 | F18: 룰렛 소환 실패 | G18: 룰렛 소환 실패 시 알림 표시 여부 확인 | H18: "룰렛 소환 실패.." 문구 노출 | I18: Pass | J18: 김가이 | K18: 2026.02.03
A19: 18 | B19: Low | E19: 소환 결과 알림 | F19: 일반(저등급) 영웅 소환 | G19: 알림 문구가 노출되지 않는지 여부 확인 | H19: 알림 미노출 확인 | I19: Pass | J19: 김가이 | K19: 2026.02.03
A20: 19 | B20: Medium | E20: 소환 결과 알림 | F20: 연속 고등급 영웅 소환 성공 | G20: 알림이 누락되거나 중복되는 현상 확인 | H20: 각각 개별 알림이 순차적으로 노출됨 | I20: Pass | J20: 김가이 | K20: 2026.02.03
A21: 20 | B21: Medium | E21: 사냥 결과 알림 | F21: 사냥 도전 성공 | G21: 사냥 성공 시 알림 표시 여부 확인 | H21: 사냥 성공 문구 출력 | I21: Pass | J21: 김가이 | K21: 2026.02.03
A22: 21 | B22: Medium | E22: 사냥 결과 알림 | F22: 사냥 도전 실패 | G22: 사냥 실패 시 알림 표시 여부 확인 | H22: 사냥 실패 문구 출력 | I22: Pass | J22: 김가이 | K22: 2026.02.03
A23: 22 | B23: Low | D23: 버튼 노출 | E23: 설정 버튼 | F23: 게임 진행 중 | G23: 우측 하단 햄버거 버튼 노출 확인 | H23: 햄버거 버튼이 정상 위치에 표시됨 | I23: Pass | J23: 김가이 | K23: 2026.02.03
A24: 23 | B24: Low | E24: 이모티콘 버튼 | F24: 게임 진행 중 | G24: 우측 하단 이모티콘 버튼 노출 확인 | H24: 버튼 클릭 시 이모티콘 선택 창 노출 | I24: Pass | J24: 김가이 | K24: 2026.02.03
A25: 24 | B25: Low | E25: 채팅 버튼 | F25: 게임 진행 중 | G25: 우측 하단 채팅 버튼 노출 확인 | H25: 채팅 버튼 노출 및 클릭 시 채팅창 표시 | I25: Pass | J25: 김가이 | K25: 2026.02.03
A26: 25 | B26: Low | E26: 설정 팝업 | F26: 설정 버튼 클릭 | G26: 설정 버튼 클릭 시 팝업이 열리는지 확인 | H26: 설정 UI 팝업 노출 | I26: Pass | J26: 김가이 | K26: 2026.02.03
A27: 26 | B27: Medium | D27: 재화 표시 | E27: 코인 수치 | F27: 게임 진행 중 | G27: 중앙 하단 골드 수치 노출 여부 확인 | H27: 보유 골드가 실시간 갱신되어 표시됨 | I27: Pass | J27: 김가이 | K27: 2026.02.03
A28: 27 | B28: Medium | E28: 행운석 수치 | F28: 게임 진행 중 | G28: 골드 수치 우측의 행운석 수치 확인 | H28: 행운석 보유 개수가 실시간 갱신되어 표시됨 | I28: Pass | J28: 김가이 | K28: 2026.02.03
A29: 28 | B29: Medium | E29: 유닛 슬롯 수 | F29: 게임 진행 중 | G29: 유닛 수치가 (현재/최대) 형식으로 표시 확인 | H29: 유닛 수가 조건에 따라 갱신 표시됨 | I29: Pass | J29: 김가이 | K29: 2026.02.03
A30: 29 | B30: High | D30: 기능 버튼 | E30: 신화 버튼 | F30: 게임 진행 중 | G30: 좌측 하단 신화 버튼 노출 확인 | H30: 클릭 시 신화 유닛 소환 팝업 노출 | I30: Pass | J30: 김가이 | K30: 2026.02.03
A31: 30 | B31: Medium | E31: 신화 버튼 | F31: 신화 조건 충족 | G31: 신화 버튼 강조 표시 확인 | H31: 소환 가능한 신화 유닛의 수가 강조되어 표시됨 | I31: Pass | J31: 김가이 | K31: 2026.02.03
A32: 31 | B32: High | E32: 소환 버튼 | F32: 게임 진행 중 | G32: 하단 중앙 소환 버튼 노출 확인 | H32: 클릭 시 유닛 소환 진행됨 | I32: Pass | J32: 김가이 | K32: 2026.02.03
A33: 32 | B33: High | E33: 룰렛 버튼 | F33: 게임 진행 중 | G33: 룰렛 버튼 노출 확인 | H33: 클릭 시 룰렛 소환 팝업 노출 | I33: Pass | J33: 김가이 | K33: 2026.02.03
A34: 33 | B34: Medium | E34: 강화 버튼 | F34: 게임 진행 중 | G34: 강화 버튼 노출 확인 | H34: 클릭 시 강화 팝업 노출 | I34: Pass | J34: 김가이 | K34: 2026.02.03
A35: 34 | B35: High | C35: 인게임 진행 | D35: 유닛 소환 | E35: 소환 가능 여부 | F35: 소환 요구 비용 충족 | G35: 소환 버튼 클릭 시 유닛 생성 | H35: 유닛이 필드에 정상 소환됨 | I35: Pass | J35: 김가이 | K35: 2026.02.03
A36: 35 | B36: Medium | E36: 소환 비용 증가 | F36: 소환 횟수 증가 | G36: 소환 비용이 점차 증가하는지 확인 | H36: 소환 비용이 증가함 | I36: Pass | J36: 김가이 | K36: 2026.02.03
A37: 36 | B37: High | E37: 최대 유닛 수 초과 | F37: 유닛 최대치 도달 상태 | G37: 추가 소환 시 소환 제한 확인 | H37: 소환 불가 안내 출력 | I37: Pass | J37: 김가이 | K37: 2026.02.03
A38: 37 | B38: High | E38: 필드 배치 불가 | F38: 필드에 유닛 모두 배치 상태 | G38: 추가 소환 시 소환 제한 확인 | H38: 소환 불가 안내 출력 | I38: Pass | J38: 김가이 | K38: 2026.02.03
A39: 38 | B39: High | E39: 동일 유닛 중첩 | F39: 유닛 소환 시 동일 유닛 필드에 존재 | G39: 동일 유닛 소환 시 최대 3개까지 자동 중첩 | H39: 동일 유닛이 정상적으로 3개까지 중첩됨 | I39: Pass | J39: 김가이 | K39: 2026.02.03
A40: 39 | B40: High | E40: 유닛 합성 | F40: 동일 유닛 3개 존재 | G40: 동일 유닛을 최대 중첩 시 상위 등급으로 합성 가능 | H40: 등급 상승 유닛 등장 | I40: Pass | J40: 김가이 | K40: 2026.02.03
...
