Workbook

Sheet 프로젝트 진행률
B2: QA Test Dashboard
B4: % of Test Cases Pass | I4: % of Test Cases Fail
B5: =AVERAGE(H51:H53) -> 0.93765063 | I5: =AVERAGE(I51:I53) -> 0.047534559
B50: 구분 | C50: Pass | D50: Fail | E50: Blocked | F50: Not Tested | G50: 전체 | H50: Pass율 | I50: Fail율
B51: 메인화면 | C51: =COUNTIF(TC_메인화면!H:H,"Pass") -> 136 | D51: =COUNTIF(TC_메인화면!H:H,"Fail") -> 13 | E51: =COUNTIF(TC_메인화면!H:H,"Blocked") -> 0 | F51: =COUNTIF(TC_메인화면!H:H,"Not Tested") -> 0 | G51: =COUNTA(TC_메인화면!H:H)-1 -> 149 | H51: =C51/G51 -> 0.91275168 | I51: =D51/G51 -> 0.087248322
B52: 튜토리얼 | C52: =COUNTIF(TC_튜토리얼!H:H,"Pass") -> 71 | D52: =COUNTIF(TC_튜토리얼!H:H,"Fail") -> 3 | E52: =COUNTIF(TC_튜토리얼!H:H,"Blocked") -> 0 | F52: =COUNTIF(TC_튜토리얼!H:H,"Not Tested") -> 0 | G52: =COUNTA(TC_튜토리얼!H:H)-1 -> 74 | H52: =C52/G52 -> 0.95945946 | I52: =D52/G52 -> 0.040540541
B53: 인게임 | C53: =COUNTIF(TC_인게임!H:H,"Pass") -> 127 | D53: =COUNTIF(TC_인게임!H:H,"Fail") -> 2 | E53: =COUNTIF(TC_인게임!H:H,"Blocked") -> 0 | F53: =COUNTIF(TC_인게임!H:H,"Not Tested") -> 6 | G53: =COUNTA(TC_인게임!H:H)-1 -> 135 | H53: =C53/G53 -> 0.94074074 | I53: =D53/G53 -> 0.014814815

Sheet TC_메인화면
B2: TC ID | C2: 대분류 | D2: 중분류 | E2: 사전 조건 | F2: 수행 액션 | G2: 기대 결과 | H2: 실제 결과 | I2: 테스트 수행자 | J2: 수행 날짜 | K2: BTS No. | L2: Notes
B3: 1 | C3: 로비 | D3: 프로필 | F3: 좌측 캐릭터 포트레이트 이미지 | G3: 사용자가 설정한 캐릭터 포트레이트 이미지 정상적으로 노출 | H3: Pass | I3: 김가이 | J3: 2025.10.16 | N3: Pass
B4: 2 | F4: 좌측 캐릭터 포트레이트 테두리 | G4: 사용자가 설정한 캐릭터 포트레이트 테두리 정상적으로 노출 | H4: Pass | I4: 김가이 | J4: 2025.10.17 | N4: Fail
B5: 3 | F5: 사용자의 닉네임 확인 | G5: 실제 사용자의 닉네임과 동일하게 표시 | H5: Pass | I5: 김가이 | J5: 2025.10.17 | N5: Blocked
B6: 4 | F6: 사용자의 랭크 듀얼 티어 | G6: 실제 사용자의 랭크 듀얼 티어와 동일하게 표시 | H6: Pass | I6: 김가이 | J6: 2025.10.17 | N6: Not Tested
B7: 5 | F7: 사용자의 MD 검정 등급 | G7: 실제 사용자의 MD 검정 등급과 동일하게 표시 | H7: Pass | I7: 김가이 | J7: 2025.10.17 | N7: N/A
B8: 6 | F8: 사용자의 레벨 정보 확인 | G8: 실제 사용자의 레벨 정보와 동일하게 표시 | H8: Pass | I8: 김가이 | J8: 2025.10.17
B9: 7 | F9: 경험치 프로그래스 바 확인 | G9: 전체 경험치 에서 현재 경험치를 채운 게이지 형태로 표시 | H9: Pass | I9: 김가이 | J9: 2025.10.17
B10: 8 | F10: 사용자 프로필 정보 영역 탭 | G10: 사용자 상세 프로필로 이동 | H10: Pass | I10: 김가이 | J10: 2025.10.17
B11: 9 | D11: 탑인포 | F11: 젬 재화 정보 표시 확인 | G11: 실제 사용자가 보유하고 있는 젬이 정상적으로 표시 | H11: Pass | I11: 김가이 | J11: 2025.10.17
B12: 10 | F12: 젬 재화 표시 영역 탭 | G12: 젬 구입 상점으로 이동 | H12: Pass | I12: 김가이 | J12: 2025.10.17
B13: 11 | F13: 듀얼 패스 버튼 탭 | G13: 듀얼 패스로 이동 | H13: Pass | I13: 김가이 | J13: 2025.10.17
B14: 12 | E14: 듀얼 패스 등급이 올라 새로운 보상을 획득할 수 있는 상태 | F14: 듀얼 패스 버튼에 레드닷 표시 여부 확인 | G14: 레드닷 정상 표시 | H14: Pass | I14: 김가이 | J14: 2025.10.17
B15: 13 | E15: 듀얼 패스 버튼에 레드닷 표시가 있는 상태 | F15: 1. 듀얼 패스 버튼 탭 2. 듀얼 패스 획득 가능 보상 수령 3. 듀얼 패스 버튼 레드닷 표시 사라짐 확인 | G15: 레드닷 사라짐 | H15: Pass | I15: 김가이 | J15: 2025.10.17
B16: 14 | F16: 정보 버튼 탭 | G16: 정보-공지로 이동 | H16: Pass | I16: 김가이 | J16: 2025.10.17
B17: 15 | E17: 신규 공지가 등록되어 있고 사용자가 공지를 확인하지 않은 상태 | F17: 정보 버튼에 레드닷 표시 여부 확인 | G17: 레드닷 정상 표시 | H17: Pass | I17: 김가이 | J17: 2025.10.17
B18: 16 | E18: 정보 버튼에 레드닷 표시가 있는 상태 | F18: 1. 정보 버튼 탭 2. 정보 공지사항 확인 3. 정보 버튼 레드닷 표시 사라짐 확인 | G18: 레드닷 사라짐 | H18: Pass | I18: 김가이 | J18: 2025.10.17
B19: 17 | F19: 기프트 상자 버튼 탭 | G19: 기프트 상자로 이동 | H19: Pass | I19: 김가이 | J19: 2025.10.17
B20: 18 | E20: 수령 가능한 선물이 있고 사용자가 선물을 수령하지 않은 상태 | F20: 기프트 상자 버튼에 레드닷 표시 여부 확인 | G20: 레드닷 정상 표시 | H20: Pass | I20: 김가이 | J20: 2025.10.17
B21: 19 | E21: 기프트 상자 버튼에 레드닷 표시가 있는 상태 | F21: 1. 기프트 상자 버튼 탭 2. 기프트 상자 선물 수령 3. 기프트 상자 레드닷 표시 사라짐 확인 | G21: 레드닷 사라짐 | H21: Pass | I21: 김가이 | J21: 2025.10.17
B22: 20 | F22: 듀얼 라이브 버튼 탭 | G22: 듀얼 라이브로 이동 | H22: Pass | I22: 김가이 | J22: 2025.10.17
B23: 21 | E23: 새로운 이벤트 관련 라이브가 있고 사용자가 확인하지 않은 상태 | F23: 듀얼 라이브 버튼에 레드닷 표시 여부 확인 | G23: 레드닷 정상 표시 | H23: Pass | I23: 김가이 | J23: 2025.10.17
B24: 22 | E24: 듀얼 라이브 버튼에 레드닷 표시가 있는 상태 | F24: 1. 듀얼 라이브 버튼 탭 2. 듀얼 라이브 이벤트 확인 3. 듀얼 라이브 버튼 레드닷 표시 사라짐 확인 | G24: 레드닷 사라짐 | H24: Pass | I24: 김가이 | J24: 2025.10.17
B25: 23 | F25: 팔로우 버튼 탭 | G25: 팔로우 팝업 노출 | H25: Pass | I25: 김가이 | J25: 2025.10.17
B26: 24 | E26: 1. 신규 팔로우 신청이 있고 사용자가 신청을 확인하지 않은 상태 2. 친구 대전 신청이 있고 사용자가 신청을 확인하지 않은 상태 | F26: 팔로우 버튼에 레드닷 표시 여부 확인 | G26: 레드닷 정상 표시 | H26: Pass | I26: 김가이 | J26: 2025.10.17
B27: 25 | E27: 팔로우 버튼에 레드닷 표시가 있는 상태 | F27: 1. 팔로우 버튼 탭 2. 팔로우 버튼 레드닷 표시 사라짐 확인 | G27: 레드닷 사라짐 | H27: Pass | I27: 김가이 | J27: 2025.10.17
B28: 26 | F28: 기타 정보 버튼 탭 | G28: 기타 정보 팝업 노출 | H28: Pass | I28: 김가이 | J28: 2025.10.17
B29: 27 | D29: 슬라이더 | F29: 슬라이더 왼쪽 화살표 버튼 탭 | G29: 슬라이더가 이전 이미지로 변경 | H29: Pass | I29: 김가이 | J29: 2025.10.17
B30: 28 | F30: 슬라이더 오른쪽 화살표 버튼 탭 | G30: 슬라이더가 다음 이미지로 변경 | H30: Pass | I30: 김가이 | J30: 2025.10.17
B31: 29 | E31: 이벤트 듀얼을 노출하고 있는 상태 | F31: 슬라이더 이벤트 듀얼 이미지 탭 | G31: 이벤트 듀얼로 이동 | H31: Pass | I31: 김가이 | J31: 2025.10.17
B32: 30 | E32: 신규 카드팩을 노출하고 있는 상태 | F32: 슬라이더 신규 카드팩 이미지 탭 | G32: 상점-카드팩 구입 페이지로 이동 | H32: Pass | I32: 김가이 | J32: 2025.10.17
B33: 31 | E33: 신규, 복귀 유저 이벤트를 노출하고 있는 상태 | F33: 슬라이더 신규, 복귀 유저 이벤트 이미지 탭 | G33: 루키&컴백 상호 팔로우 캠페인 팝업 노출 | H33: Pass | I33: 김가이 | J33: 2025.10.17
B34: 32 | E34: 듀얼 라이브를 노출하고 있는 상태 | F34: 슬라이더 듀얼 라이브 이미지 탭 | G34: 듀얼 라이브로 이동 | H34: Pass | I34: 김가이 | J34: 2025.10.17
B35: 33 | E35: 슬라이더 조작을 하지 않은 상태 | F35: 슬라이더가 5초마다 넘어가는지 여부 확인 | G35: 슬라이더 정상적으로 작동 | H35: Pass | I35: 김가이 | J35: 2025.10.17
B36: 34 | D36: 미션 | F36: 미션 버튼 탭 | G36: 미션으로 이동 | H36: Pass | I36: 김가이 | J36: 2025.10.17
B37: 35 | F37: 미션의 남은 기한 표시 여부 확인 | G37: 미션의 남은 기한이 정상적으로 표시 | H37: Pass | I37: 김가이 | J37: 2025.10.17
B38: 36 | F38: 클리어 조건 미달성 미션 표시 여부 확인 | G38: 클리어 조건 미달성 미션 정상적으로 표시 | H38: Pass | I38: 김가이 | J38: 2025.10.17
B39: 37 | E39: 클리어 조건을 달성한 미션이 있고 사용자가 미션 완료 보상을 수령하지 않은 상태 | F39: 미션 버튼에 레드닷 표시 여부 확인 | G39: 레드닷 정상 표시 | H39: Pass | I39: 김가이 | J39: 2025.10.17
B40: 38 | D40: 핵심 컨텐츠 이동 버튼 | F40: 듀얼 메뉴 버튼 탭 | G40: 듀얼 메뉴로 이동 | H40: Fail | I40: 김가이 | J40: 2025.10.17
B41: 39 | F41: 덱 버튼 탭 | G41: 마이 덱으로 이동 | H41: Fail | I41: 김가이 | J41: 2025.10.17
...

Sheet TC_튜토리얼
B2: TC ID | C2: 대분류 | D2: 중분류 | E2: 사전 조건 | F2: 수행 액션 | G2: 기대 결과 | H2: 실제 결과 | I2: 테스트 수행자 | J2: 수행 날짜 | K2: BTS No. | L2: Notes
B3: 1 | C3: 튜토리얼 | D3: 진행 | E3: 튜토리얼 화면 진입 | F3: 플레이 버튼 터치 | G3: "당신은 후공입니다" 텍스트 표시 | H3: Fail | I3: 김가이 | J3: 2025.10.19 | N3: Pass
B4: 2 | E4: 튜토리얼 진입 | F4: 로딩 대기 | G4: "상대의 라이프 포인트(LP)를 0으로 만들어봅시다" 텍스트 표시 | H4: Fail | I4: 김가이 | J4: 2025.10.19 | N4: Fail
B5: 3 | E5: "상대의 라이프 포인트(LP)를 0으로 만들어봅시다" 텍스트 표시 | F5: 화면 탭 | G5: 상대가 "디지트론" 카드를 일반 소환하고 턴을 종료 | H5: Fail | I5: 김가이 | J5: 2025.10.19 | N5: Blocked
B6: 4 | E6: 상대가 "디지트론" 카드를 일반 소환하고 턴을 종료 | F6: 화면 탭 | G6: "성잔에 이끌린 자" 카드를 드로우 후 카드 확대 표시 | H6: Pass | I6: 김가이 | J6: 2025.10.19 | N6: Not Tested
B7: 5 | E7: "성잔에 이끌린 자" 카드를 드로우 후 카드 확대 표시 | F7: 화면 탭 | G7: 카드 축소화 후 "몬스터 카드를 드로우했습니다" 텍스트 표시 | H7: Pass | I7: 김가이 | J7: 2025.10.19 | N7: N/A
B8: 6 | E8: 몬스터 카드를 드로우했습니다 텍스트 표시 | F8: 화면 탭 | G8: "몬스터를 일반 소환해봅시다" 텍스트 표시 | H8: Pass | I8: 김가이 | J8: 2025.10.19
B9: 7 | E9: "몬스터를 일반 소환해봅시다" 텍스트 표시 | F9: 몬스터 카드 탭 | G9: 몬스터 카드 선택 상태 활성화, 카드 정보 표시 | H9: Pass | I9: 김가이 | J9: 2025.10.19
B10: 8 | E10: "몬스터를 일반 소환해봅시다" 텍스트 표시 | F10: 몬스터 카드 드래그 | G10: 카드 선택 상태 활성화, 필드 선택 상태 활성화, 카드 정보 표시 | H10: Pass | I10: 김가이 | J10: 2025.10.19
B11: 9 | E11: "몬스터를 일반 소환해봅시다" 텍스트 표시 | F11: 페이즈 버튼 탭 | G11: 페이즈 선택 팝업 노출 | H11: Pass | I11: 김가이 | J11: 2025.10.19
B12: 10 | E12: "배틀 페이즈로 이동하여, 공격해 봅시다" 텍스트 표시 | F12: 화면 탭 | G12: 페이즈 버튼 강조 표시 | H12: Pass | I12: 김가이 | J12: 2025.10.19
B13: 11 | E13: "일반 소환은 1턴에 1번만 실행할 수 있습니다" 텍스트 표시 | F13: 화면 탭 | G13: "배틀 페이즈로 이동하여, 공격해 봅시다" 텍스트 표시 | H13: Pass | I13: 김가이 | J13: 2025.10.19
B14: 12 | E14: "몬스터를 공격해봅시다" 텍스트 표시 | F14: 화면 탭 | G14: 배틀 페이즈 이동 | H14: Pass | I14: 김가이 | J14: 2025.10.19
B15: 13 | E15: "상대 몬스터의 공격력을 넘은 만큼만 상대의 LP에 데미지를 줍니다" 텍스트 표시 | F15: 화면 탭 | G15: "턴을 종료합시다" 텍스트 표시 | H15: Pass | I15: 김가이 | J15: 2025.10.19
B16: 14 | E16: "턴을 종료합시다" 텍스트 표시 | F16: 화면 탭 | G16: 페이즈 버튼 강조 표시 | H16: Pass | I16: 김가이 | J16: 2025.10.19
B17: 15 | E17: "End를 선택해주세요" 텍스트 표시 | F17: 화면 탭 | G17: 상대 턴 시작, 상대가 "네오 버그" 카드를 드로우 후 일반 소환하고 턴을 종료 | H17: Pass | I17: 김가이 | J17: 2025.10.19
B18: 16 | E18: "마법 카드를 드로우 했습니다" 텍스트 표시 | F18: 화면 탭 | G18: "마법 카드를 발동해봅시다" 텍스트 표시 | H18: Pass | I18: 김가이 | J18: 2025.10.19
B19: 17 | E19: "마법 카드를 발동해봅시다" 텍스트 표시 | F19: 몬스터 카드 탭 | G19: 몬스터 카드 선택 상태 활성화, 카드 정보 표시 | H19: Pass | I19: 김가이 | J19: 2025.10.19
... B24: 22 | E24: "상대 몬스터가 없을 경우의 공격은, 상대 플레이어로의 직접 공격이 됩니다" 텍스트 표시 | F24: 화면 탭 | G24: 배틀 페이즈 이동 | H24: Pass | I24: 김가이 | J24: 2025.10.19
B25: 23 | D25: 화면 조작 | E25: 페이즈 선택 팝업 노출 | F25: 취소 버튼 탭 | G25: 페이즈 선택 팝업 닫음 | H25: Pass | I25: 김가이 | J25: 2025.10.19
B26: 24 | E26: 페이즈 선택 팝업 노출 | F26: 메인 페이즈 1 버튼 탭 | G26: 페이즈 선택 팝업 닫음 | H26: Pass | I26: 김가이 | J26: 2025.10.19
B27: 25 | E27: 페이즈 선택 팝업 노출 | F27: 배틀 페이즈 버튼 탭 | G27: "일반 소환을 선택해주세요" 텍스트 표시 | H27: Pass | I27: 김가이 | J27: 2025.10.19
B28: 26 | E28: 페이즈 선택 팝업 노출 | F28: 엔드 페이즈 버튼 탭 | G28: "일반 소환을 선택해주세요" 텍스트 표시 | H28: Pass | I28: 김가이 | J28: 2025.10.19
B29: 27 | E29: 패의 카드 선택 상태 활성화 | F29: 일반 소환 버튼 탭 | G29: 필드 선택 상태 활성화 | H29: Pass | I29: 김가이 | J29: 2025.10.19
B30: 28 | E30: 패의 카드 선택 상태 활성화 | F30: 세트 버튼 탭 | G30: "일반 소환을 선택해주세요" 텍스트 표시 | H30: Pass | I30: 김가이 | J30: 2025.10.19
B31: 29 | E31: 카드 선택 상태 활성화 | F31: 카드 정보의 카드 이미지 탭 | G31: 카드 세부 정보 표시 | H31: Pass | I31: 김가이 | J31: 2025.10.19
B32: 30 | E32: 카드 세부 정보 표시 | F32: 카드 세부 정보의 바깥 영역 탭 | G32: 카드 세부 정보 표시 닫음 | H32: Pass | I32: 김가이 | J32: 2025.10.19
B33: 31 | E33: 카드 세부 정보 표시 | F33: 카드 세부 정보의 카드 이미지 탭 | G33: 카드 이미지 확대 표시 | H33: Pass | I33: 김가이 | J33: 2025.10.19
B34: 32 | E34: 카드 이미지 확대 표시 | F34: 카드 이미지 바깥 영역 탭 | G34: 카드 이미지 확대 표시 닫음 | H34: Pass | I34: 김가이 | J34: 2025.10.19
B35: 33 | E35: 필드 선택 상태 활성화 | F35: 1번 메인 몬스터 존 선택 | G35: 카드가 1번 메인 몬스터 존으로 이동, "일반 소환은 1턴에 1번만 실행할 수 있습니다" 텍스트 표시 | H35: Pass | I35: 김가이 | J35: 2025.10.19
B36: 34 | E36: 필드 선택 상태 활성화 | F36: 2번 메인 몬스터 존 선택 | G36: 카드가 2번 메인 몬스터 존으로 이동, "일반 소환은 1턴에 1번만 실행할 수 있습니다" 텍스트 표시 | H36: Pass | I36: 김가이 | J36: 2025.10.19
B37: 35 | E37: 필드 선택 상태 활성화 | F37: 3번 메인 몬스터 존 선택 | G37: 카드가 3번 메인 몬스터 존으로 이동, "일반 소환은 1턴에 1번만 실행할 수 있습니다" 텍스트 표시 | H37: Pass | I37: 김가이 | J37: 2025.10.19
... B45: 43 | E45: 배틀 페이즈로 이동 예/아니오 확인 팝업 출력 | F45: 예 버튼 탭 | G45: "몬스터를 공격해봅시다" 텍스트 표시 | H45: Pass | I45: 김가이 | J45: 2025.10.19
B46: 44 | E46: 배틀 페이즈 이동 | G46: 몬스터 카드 활성화 | H46: Pass | I46: 김가이 | J46: 2025.10.19
B47: 45 | E47: 몬스터 카드 활성화 | F47: 카드 탭 | G47: 카드 선택 상태 활성화 | H47: Pass | I47: 김가이 | J47: 2025.10.19
B48: 46 | E48: 몬스터 카드 활성화 | F48: 카드 드래그 후 공격할 대상 지정 | G48: 카드 선택 상태 활성화, 상대 몬스터 공격 | H48: Pass | I48: 김가이 | J48: 2025.10.19
B49: 47 | E49: 필드의 카드 선택 상태 활성화 | F49: 공격 버튼 탭 | G49: 상대 몬스터 카드가 파괴되어 묘지 이동, 상대 몬스터의 공격력 차이 만큼 상대 체력 감소, "상대 몬스터의 공격력을 넘은 만큼만 상대의 LP에 데미지를 줍니다" 텍스트 표시 | H49: Pass | I49: 김가이 | J49: 2025.10.19
B50: 48 | E50: 페이즈 버튼 활성화 | F50: 페이즈 버튼 탭 | G50: 페이즈 선택 팝업 노출 | H50: Pass | I50: 김가이 | J50: 2025.10.19
B51: 49 | E51: 페이즈 선택 팝업 노출 | F51: 배틀 페이즈 버튼 탭 | G51: 페이즈 선택 팝업 닫음 | H51: Pass | I51: 김가이 | J51: 2025.10.19
B52: 50 | E52: 페이즈 선택 팝업 노출 | F52: 메인 페이즈 2 버튼 탭 | G52: "End를 선택해주세요" 텍스트 표시 | H52: Pass | I52: 김가이 | J52: 2025.10.19
...

Sheet TC_인게임
B2: TC ID | C2: 대분류 | D2: 중분류 | E2: 사전 조건 | F2: 수행 액션 | G2: 기대 결과 | H2: 실제 결과 | I2: 테스트 수행자 | J2: 수행 날짜 | K2: BTS No. | L2: Notes
B3: 1 | C3: 듀얼 | D3: 매칭 | E3: 게임 진입 중 인터넷 연결이 끊어졌을 때 | F3: 게임 진입 실패 | G3: 게임 진입 실패와 인터넷 연결 문제 메세지 출력 | H3: Fail | I3: 김가이 | J3: 2025.10.20 | N3: Pass
B4: 2 | E4: 게임 진입 중 상대의 연결이 끊어졌을 때 | F4: 로딩 지연, 게임 진입 실패 | G4: 상대 연결 끊김 메세지 출력 | H4: Fail | I4: 김가이 | J4: 2025.10.20 | N4: Fail
B5: 3 | D5: 드로우 | E5: 게임 시작 | F5: 서로 덱에서 카드 5장씩 드로우 후 선공 플레이어의 턴 진행 여부 확인 | G5: 서로 덱에서 카드 5장씩 드로우 후 선공 플레이어의 턴 정상 진행 | H5: Pass | I5: 김가이 | J5: 2025.10.20 | N5: Blocked
B6: 4 | E6: 턴을 진행하고 있고 드로우 페이즈일때 | F6: 덱에서 카드 1장을 드로우 | G6: 덱에서 카드 1장을 드로우 | H6: Pass | I6: 김가이 | J6: 2025.10.20 | N6: Not Tested
B7: 5 | E7: 턴을 진행하고 있고 드로우 페이즈이며 선공 플레이어의 첫번째 턴일 경우 | F7: 드로우 페이즈 실행, 드로우하지 않음 | G7: 드로우 페이즈는 실행하지만 카드는 드로우하지 않음 | H7: Pass | I7: 김가이 | J7: 2025.10.20 | N7: N/A
B8: 6 | E8: 덱에서 드로우해야 하는 카드의 효과가 적용되었을 때 | F8: 덱에서 카드 1장을 드로우 | G8: 덱에서 카드 1장을 드로우 | H8: Pass | I8: 김가이 | J8: 2025.10.20
B9: 7 | E9: 드로우를 시행해야 할 때 덱의 카드가 0장일 경우 | F9: 더 이상 드로우 할 수 없을 때 게임 패배 | G9: 드로우 할 수 없을 때 게임 패배 | H9: Pass | I9: 김가이 | J9: 2025.10.20
B10: 8 | D10: 배틀 (배틀 스텝* = 공격 선언- 데미지 스텝 개시- 데미지 계산- 데미지 스텝 종료) | E10: 공격 표시 카드가 뒷면 수비 표시 카드를 공격 선언했을 경우 | F10: 1. 배틀 스텝으로 진입해 배틀 스텝 과정 진행 2. 데미지 계산 단계에서 뒷면 수비 표시 카드 리버스(앞면 수비 표시) | G10: 뒷면 수비 표시 카드가 앞면 수비 표시 카드로 리버스 | H10: Pass | I10: 김가이 | J10: 2025.10.20
B11: 9 | E11: 사용자의 공격 표시 카드가 상대 수비 표시 카드를 공격했을 때, (사용자의 공격력 > 상대 수비력) 일 경우 | F11: 1. 배틀 스텝으로 진입해 배틀 스텝 과정 진행 2. 데미지 계산 단계에서 상대 수비 표시 카드 파괴 | G11: 상대 수비 표시 카드가 파괴 | H11: Pass | I11: 김가이 | J11: 2025.10.20
B12: 10 | E12: 사용자의 공격 표시 카드가 관통 효과를 가지고 있고 상대 수비 표시 카드를 공격했을 때, (사용자의 공격력 > 상대 수비력) 일 경우 | F12: 1. 배틀 스텝으로 진입해 배틀 스텝 과정 진행 2. 데미지 계산 단계에서 상대 수비 표시 카드 파괴, 공격 표시 카드의 공격력과 수비 표시 카드의 수비력 차이 만큼 상대 라이프 포인트에 전투 데미지 | G12: 상대 수비 표시 카드가 파괴, 상대 라이프 포인트에 전투 데미지 적용 | H12: Pass | I12: 김가이 | J12: 2025.10.20
B13: 11 | E13: 사용자의 공격 표시 카드가 상대 수비 표시 카드를 공격했을 때, (사용자의 공격력 < 상대 수비력) 일 경우 | F13: 1. 배틀 스텝으로 진입해 배틀 스텝 과정 진행 2. 데미지 계산 단계에서 사용자의 공격 표시 카드의 공격력과 상대 수비 표시 카드의 수비력 차이 만큼 사용자 라이프 포인트에 전투 데미지 | G13: 사용자 라이프 포인트에 전투 데미지 적용 | H13: Pass | I13: 김가이 | J13: 2025.10.20
B14: 12 | E14: 사용자의 공격 표시 카드가 상대 수비 표시 카드를 공격했을 때, (사용자의 공격력 = 상대 수비력) 일 경우 | F14: 1. 배틀 스텝으로 진입해 배틀 스텝 과정 진행 2. 데미지 계산 단계에서 아무 처리를 하지 않음 | G14: 서로에게 아무 처리도 일어나지 않음 | H14: Pass | I14: 김가이 | J14: 2025.10.20
B15: 13 | E15: 사용자의 공격 표시 카드가 상대 공격 표시 카드를 공격했을 때, (사용자의 공격력 = 상대 공격력) 일 경우 | F15: 1. 배틀 스텝으로 진입해 배틀 스텝 과정 진행 2. 데미지 계산 단계에서 서로의 카드 파괴 | G15: 서로의 공격 표시 카드 파괴 | H15: Pass | I15: 김가이 | J15: 2025.10.20
B16: 14 | E16: 사용자의 공격 표시 카드가 상대 공격 표시 카드를 공격했을 때, 서로의 공격력이 0일 경우 | F16: 1. 배틀 스텝으로 진입해 배틀 스텝 과정 진행 2. 데미지 계산 단계에서 아무 처리를 하지 않음 | G16: 서로에게 아무 처리도 일어나지 않음 | H16: Pass | I16: 김가이 | J16: 2025.10.20
B17: 15 | E17: 사용자의 공격 표시 카드가 상대 공격 표시 카드를 공격했을 때, (사용자의 공격력 > 상대 공격력) 일 경우 | F17: 1. 배틀 스텝으로 진입해 배틀 스텝 과정 진행 2. 데미지 계산 단계에서 사용자의 공격 표시 카드의 공격력과 상대 공격 표시 카드의 공격력 차이 만큼 상대 라이프 포인트에 전투 데미지 | G17: 상대 공격 표시 카드가 파괴, 상대 라이프 포인트에 전투 데미지 적용 | H17: Pass | I17: 김가이 | J17: 2025.10.20
B18: 16 | E18: 사용자의 공격 표시 카드가 상대 공격 표시 카드를 공격했을 때, (사용자의 공격력 < 상대 공격력) 일 경우 | F18: 1. 배틀 스텝으로 진입해 배틀 스텝 과정 진행 2. 데미지 계산 단계에서 사용자 공격 표시 카드 파괴, 사용자의 공격 표시 카드의 공격력과 상대 공격 표시 카드의 공격력 차이 만큼 사용자 라이프 포인트에 전투 데미지 | G18: 사용자의 공격 표시 카드가 파괴, 사용자 라이프 포인트에 전투 데미지 적용 | H18: Pass | I18: 김가이 | J18: 2025.10.20
B19: 17 | E19: 사용자의 공격 표시 카드가 상대 플레이어를 직접 공격했을 경우 | F19: 1. 배틀 스텝으로 진입해 배틀 스텝 과정 진행 2. 데미지 계산 단계에서 사용자의 공격 표시 카드의 공격력만큼 상대 라이프 포인트에 전투 데미지 | G19: 사용자의 공격 표시 카드의 공격력만큼 상대 라이프 포인트에 전투 데미지 적용 | H19: Pass | I19: 김가이 | J19: 2025.10.20
B20: 18 | E20: 상대 필드에 몬스터 카드가 존재하고 공격 선언할 카드가 직접 공격 몬스터가 아닐 경우 | F20: 상대 플레이어에게 직접 공격 불가능 확인 | G20: 상대 플레이어에게 직접 공격 불가능 확인 | H20: Pass | I20: 김가이 | J20: 2025.10.20
B21: 19 | E21: 상대 필드에 몬스터 카드가 존재하고 공격 선언할 카드가 직접 공격 몬스터일 경우 | F21: 상대 플레이어에게 직접 공격 가능 확인 | G21: 상대 플레이어에게 직접 공격 불가능 확인 | H21: Pass | I21: 김가이 | J21: 2025.10.20
B22: 20 | F22: 전투로 파괴된 몬스터가 묘지로 이동하는지 확인 | G22: 전투로 파괴된 몬스터가 묘지로 이동 확인 | H22: Pass | I22: 김가이 | J22: 2025.10.20
B23: 21 | E23: 선공 플레이어의 첫번째 턴일 경우 | F23: 선공 플레이어의 첫번째 턴에 공격 선언 불가능, 배틀 페이즈 진입 불가능 확인 | G23: 선공 플레이어의 첫번째 턴에 공격 선언 불가능, 배틀 페이즈 진입 불가능 확인 | H23: Pass | I23: 김가이 | J23: 2025.10.20
B24: 22 | D24: 효과&소환 | E24: 카드가 효과 발동 가능한 경우 | F24: 사용자가 효과 발동 가능한 카드 노란색 테두리 표시 | G24: 효과 발동 가능한 카드 노란색 테두리 정상 표시 | H24: Pass | I24: 김가이 | J24: 2025.10.20
B25: 23 | E25: 패의 카드가 필드로 소환 가능한 경우 | F25: 하단 패 중 소환 가능한 패의 카드 파란색 두꺼운 테두리 표시 | G25: 하단 패 중 소환 가능한 패의 카드 파란색 두꺼운 테두리 표시 | H25: Pass | I25: 김가이 | J25: 2025.10.20
B26: 24 | E26: 패의 카드가 필드로 세트 가능한 경우 | F26: 하단 패 중 세트 가능한 패의 카드 파란색 얇은 테두리 표시 | G26: 하단 패 중 세트 가능한 패의 카드 파란색 얇은 테두리 표시 | H26: Pass | I26: 김가이 | J26: 2025.10.20
B27: 25 | E27: 일반 소환권을 아직 사용하지 않았을 경우 | F27: 패의 4레벨 이하 몬스터 카드 소환 가능 확인 | G27: 패의 4레벨 이하 몬스터 카드 공격, 수비표시 소환 가능 확인 | H27: Pass | I27: 김가이 | J27: 2025.10.20
B28: 26 | E28: 일반 소환권을 아직 사용하지 않았을 경우 | F28: 패의 6,7 레벨 몬스터 카드를 소환할 때, 필드의 몬스터 카드 1장을 코스트로 어드밴스 소환하는지 확인 | G28: 패의 6,7 레벨 이상 몬스터 카드를 소환할 때, 필드의 몬스터 카드 1장을 코스트로 어드밴스 소환 확인 | H28: Pass | I28: 김가이 | J28: 2025.10.20
B29: 27 | E29: 일반 소환권을 아직 사용하지 않았을 경우 | F29: 패의 8,9 레벨 몬스터 카드를 소환할 때, 필드의 몬스터 카드 2장을 코스트로 어드밴스 소환하는지 확인 | G29: 패의 8,9 레벨 몬스터 카드를 소환할 때, 필드의 몬스터 카드 2장을 코스트로 어드밴스 소환 확인 | H29: Pass | I29: 김가이 | J29: 2025.10.20
B30: 28 | F30: 필드의 뒷면 수비 표시 카드를 반전 소환할 때 앞면 공격 표시로 변경 확인 | G30: 필드의 뒷면 수비 표시 카드를 반전 소환할 때 앞면 공격 표시 변경 확인 | H30: Pass | I30: 김가이 | J30: 2025.10.20
B31: 29 | E31: 이미 이번 턴에 소환되었거나 표시 형식을 변경한 카드일 경우 | F31: 몬스터 카드의 공격/수비 표시 형식 변경 불가능 확인 | G31: 몬스터 카드의 공격/수비 표시 형식 변경 불가능 확인 | H31: Pass | I31: 김가이 | J31: 2025.10.20
B32: 30 | E32: 어드밴스 소환 했을 경우 | F32: 어드밴스 소환에 사용된 필드의 카드가 묘지로 이동하는지 확인 | G32: 어드밴스 소환에 사용된 필드의 카드 묘지로 이동 확인 | H32: Pass | I32: 김가이 | J32: 2025.10.20
B33: 31 | E33: 융합 소환 했을 경우 | F33: 융합 소환의 소재된 카드가 묘지로 이동하는지 확인 | G33: 융합 소환에 사용된 카드 묘지 이동 확인 | H33: Pass | I33: 김가이 | J33: 2025.10.20
B34: 32 | E34: 싱크로 소환 했을 경우 | F34: 싱크로 소환의 소재가 된 카드가 묘지로 이동하는지 확인 | G34: 싱크로 소환에 사용된 카드 묘지 이동 확인 | H34: Pass | I34: 김가이 | J34: 2025.10.20
B35: 33 | E35: 엑시즈 소환 했을 경우 | F35: 엑시즈 소환의 소재가 된 카드가 액시즈 소환된 카드에 겹쳐지는지 확인 | G35: 엑시즈 소환에 사용된 카드가 소환된 카드에 겹쳐짐 확인 | H35: Pass | I35: 김가이 | J35: 2025.10.20
B36: 34 | E36: 링크 소환 했을 경우 | F36: 링크 소환의 소재가 된 카드가 묘지로 이동하는지 확인 | G36: 링크 소환에 사용된 카드 묘지 이동 확인 | H36: Pass | I36: 김가이 | J36: 2025.10.20
B37: 35 | E37: 엑스트라 몬스터 존에 자신의 링크 몬스터가 없을 때 링크 소환할 경우 | F37: 첫번째 링크 소환하는 카드가 엑스트라 몬스터 존에만 소환되는지 확인 | G37: 첫번째 링크 소환하는 카드가 엑스트라 몬스터 존에만 소환 확인 | H37: Pass | I37: 김가이 | J37: 2025.10.20
B38: 36 | D38: 페이즈 진행 | E38: 현재 턴이 상대 사용자의 턴일 경우 | F38: 페이즈 버튼이 붉은 색으로 표시되며 페이즈 조작 불가 | G38: 페이즈 버튼이 붉은 색으로 표시되며 버튼 조작 불가 | H38: Pass | I38: 김가이 | J38: 2025.10.20
B39: 37 | E39: 현재 턴이 사용자의 턴일 경우 | F39: 페이즈 버튼이 푸른 색으로 표시되며 페이즈 조작 가능 | G39: 페이즈 버튼이 푸른 색으로 표시되며 버튼 조작 가능 | H39: Pass | I39: 김가이 | J39: 2025.10.20
B40: 38 | E40: 페이즈 버튼을 탭 했을 경우 | F40: 페이즈 선택 팝업 표시 | G40: 페이즈 선택 팝업 표시 | H40: Pass | I40: 김가이 | J40: 2025.10.20
B41: 39 | E41: 페이즈 선택 팝업 표시 | F41: 페이즈 버튼 탭 | G41: 선택한 페이즈로 이동 | H41: Pass | I41: 김가이 | J41: 2025.10.20
...
